<?xml version="1.0" encoding="UTF-8"?>
<robot name="acrobot">
  <link name="base">
    <visual>
      <geometry>
        <box size="0.2 0.2 0.2"/>
      </geometry>
    </visual>
    <inertial>
      <mass value="1.0"/>
      <origin rpy="0 0 0" xyz="0 0 0"/>
      <inertia ixx="0.01" ixy="0.0" ixz="0.0" iyy="0.01" iyz="0.0" izz="0.01"/>
    </inertial>
  </link>

  <link name="link1">
    <visual>
      <geometry>
        <box size="0.1 1.0 0.1"/>
      </geometry>
    </visual>
    <collision>
      <geometry>
        <box size="0.1 1.0 0.1"/>
      </geometry>
    </collision>
    <inertial>
      <mass value="1.0"/>
      <origin rpy="0 0 0" xyz="0 0.5 0"/>
      <inertia ixx="0.01" ixy="0.0" ixz="0.0" iyy="0.01" iyz="0.0" izz="0.01"/>
    </inertial>
  </link>

  <link name="link2">
    <visual>
      <geometry>
        <box size="0.1 1.0 0.1"/>
      </geometry>
    </visual>
    <collision>
      <geometry>
        <box size="0.1 1.0 0.1"/>
      </geometry>
    </collision>
    <inertial>
      <mass value="1.0"/>
      <origin rpy="0 0 0" xyz="0 1.5 0"/>
      <inertia ixx="0.01" ixy="0.0" ixz="0.0" iyy="0.01" iyz="0.0" izz="0.01"/>
    </inertial>
  </link>

  <joint name="base_to_link1" type="fixed">
    <parent link="base"/>
    <child link="link1"/>
    <origin rpy="0 0 0" xyz="0 0 0"/>
  </joint>

  <joint name="link1_to_link2" type="revolute">
    <parent link="link1"/>
    <child link="link2"/>
    <origin rpy="0 0 0" xyz="0 1.0 0"/>
    <axis xyz="0 0 1"/>
    <limit effort="10" lower="-3.1415" upper="3.1415" velocity="10"/>
  </joint>
</robot>